<?xml version="1.0" encoding="UTF-8"?>
<!-- Generated by org.testng.reporters.JUnitReportReporter -->
<testsuite hostname="FIN-IT-LT-236" failures="3" tests="5" name="testCase.TC003_LoginDDT" time="19.236" errors="0" timestamp="2025-02-14T15:42:54 IST" skipped="0">
  <testcase classname="testCase.TC003_LoginDDT" name="verify_loginDDT" time="4.434"/>
  <testcase classname="testCase.TC003_LoginDDT" name="verify_loginDDT" time="4.107">
    <failure message="Exception occurred during test execution." type="java.lang.AssertionError">
      <![CDATA[java.lang.AssertionError: Exception occurred during test execution.
at org.testng.Assert.fail(Assert.java:111)
at testCase.TC003_LoginDDT.verify_loginDDT(TC003_LoginDDT.java:57)
at java.base/jdk.internal.reflect.NativeMethodAccessorImpl.invoke0(Native Method)
at java.base/jdk.internal.reflect.NativeMethodAccessorImpl.invoke(NativeMethodAccessorImpl.java:62)
at java.base/jdk.internal.reflect.DelegatingMethodAccessorImpl.invoke(DelegatingMethodAccessorImpl.java:43)
at java.base/java.lang.reflect.Method.invoke(Method.java:566)
at org.testng.internal.invokers.MethodInvocationHelper.invokeMethod(MethodInvocationHelper.java:141)
at org.testng.internal.invokers.TestInvoker.invokeMethod(TestInvoker.java:686)
at org.testng.internal.invokers.TestInvoker.invokeTestMethod(TestInvoker.java:230)
at org.testng.internal.invokers.MethodRunner.runInSequence(MethodRunner.java:63)
at org.testng.internal.invokers.TestInvoker$MethodInvocationAgent.invoke(TestInvoker.java:992)
at org.testng.internal.invokers.TestInvoker.invokeTestMethods(TestInvoker.java:203)
at org.testng.internal.invokers.TestMethodWorker.invokeTestMethods(TestMethodWorker.java:154)
at org.testng.internal.invokers.TestMethodWorker.run(TestMethodWorker.java:134)
at java.base/java.util.ArrayList.forEach(ArrayList.java:1541)
at org.testng.TestRunner.privateRun(TestRunner.java:739)
at org.testng.TestRunner.run(TestRunner.java:614)
at org.testng.SuiteRunner.runTest(SuiteRunner.java:421)
at org.testng.SuiteRunner.runSequentially(SuiteRunner.java:413)
at org.testng.SuiteRunner.privateRun(SuiteRunner.java:373)
at org.testng.SuiteRunner.run(SuiteRunner.java:312)
at org.testng.SuiteRunnerWorker.runSuite(SuiteRunnerWorker.java:52)
at org.testng.SuiteRunnerWorker.run(SuiteRunnerWorker.java:95)
at org.testng.TestNG.runSuitesSequentially(TestNG.java:1274)
at org.testng.TestNG.runSuitesLocally(TestNG.java:1208)
at org.testng.TestNG.runSuites(TestNG.java:1112)
at org.testng.TestNG.run(TestNG.java:1079)
at org.apache.maven.surefire.testng.TestNGExecutor.run(TestNGExecutor.java:308)
at org.apache.maven.surefire.testng.TestNGXmlTestSuite.execute(TestNGXmlTestSuite.java:71)
at org.apache.maven.surefire.testng.TestNGProvider.invoke(TestNGProvider.java:113)
at org.apache.maven.surefire.booter.ForkedBooter.runSuitesInProcess(ForkedBooter.java:385)
at org.apache.maven.surefire.booter.ForkedBooter.execute(ForkedBooter.java:162)
at org.apache.maven.surefire.booter.ForkedBooter.run(ForkedBooter.java:507)
at org.apache.maven.surefire.booter.ForkedBooter.main(ForkedBooter.java:495)
]]>
    </failure>
  </testcase> <!-- verify_loginDDT -->
  <testcase classname="testCase.TC003_LoginDDT" name="verify_loginDDT" time="5.214"/>
  <testcase classname="testCase.TC003_LoginDDT" name="verify_loginDDT" time="1.592">
    <failure message="Login succeeded for invalid credentials. expected [true] but found [false]" type="java.lang.AssertionError">
      <![CDATA[java.lang.AssertionError: Login succeeded for invalid credentials. expected [true] but found [false]
at org.testng.Assert.fail(Assert.java:111)
at org.testng.Assert.failNotEquals(Assert.java:1578)
at org.testng.Assert.assertTrue(Assert.java:57)
at testCase.TC003_LoginDDT.verify_loginDDT(TC003_LoginDDT.java:50)
at java.base/jdk.internal.reflect.NativeMethodAccessorImpl.invoke0(Native Method)
at java.base/jdk.internal.reflect.NativeMethodAccessorImpl.invoke(NativeMethodAccessorImpl.java:62)
at java.base/jdk.internal.reflect.DelegatingMethodAccessorImpl.invoke(DelegatingMethodAccessorImpl.java:43)
at java.base/java.lang.reflect.Method.invoke(Method.java:566)
at org.testng.internal.invokers.MethodInvocationHelper.invokeMethod(MethodInvocationHelper.java:141)
at org.testng.internal.invokers.TestInvoker.invokeMethod(TestInvoker.java:686)
at org.testng.internal.invokers.TestInvoker.invokeTestMethod(TestInvoker.java:230)
at org.testng.internal.invokers.MethodRunner.runInSequence(MethodRunner.java:63)
at org.testng.internal.invokers.TestInvoker$MethodInvocationAgent.invoke(TestInvoker.java:992)
at org.testng.internal.invokers.TestInvoker.invokeTestMethods(TestInvoker.java:203)
at org.testng.internal.invokers.TestMethodWorker.invokeTestMethods(TestMethodWorker.java:154)
at org.testng.internal.invokers.TestMethodWorker.run(TestMethodWorker.java:134)
at java.base/java.util.ArrayList.forEach(ArrayList.java:1541)
at org.testng.TestRunner.privateRun(TestRunner.java:739)
at org.testng.TestRunner.run(TestRunner.java:614)
at org.testng.SuiteRunner.runTest(SuiteRunner.java:421)
at org.testng.SuiteRunner.runSequentially(SuiteRunner.java:413)
at org.testng.SuiteRunner.privateRun(SuiteRunner.java:373)
at org.testng.SuiteRunner.run(SuiteRunner.java:312)
at org.testng.SuiteRunnerWorker.runSuite(SuiteRunnerWorker.java:52)
at org.testng.SuiteRunnerWorker.run(SuiteRunnerWorker.java:95)
at org.testng.TestNG.runSuitesSequentially(TestNG.java:1274)
at org.testng.TestNG.runSuitesLocally(TestNG.java:1208)
at org.testng.TestNG.runSuites(TestNG.java:1112)
at org.testng.TestNG.run(TestNG.java:1079)
at org.apache.maven.surefire.testng.TestNGExecutor.run(TestNGExecutor.java:308)
at org.apache.maven.surefire.testng.TestNGXmlTestSuite.execute(TestNGXmlTestSuite.java:71)
at org.apache.maven.surefire.testng.TestNGProvider.invoke(TestNGProvider.java:113)
at org.apache.maven.surefire.booter.ForkedBooter.runSuitesInProcess(ForkedBooter.java:385)
at org.apache.maven.surefire.booter.ForkedBooter.execute(ForkedBooter.java:162)
at org.apache.maven.surefire.booter.ForkedBooter.run(ForkedBooter.java:507)
at org.apache.maven.surefire.booter.ForkedBooter.main(ForkedBooter.java:495)
]]>
    </failure>
  </testcase> <!-- verify_loginDDT -->
  <testcase classname="testCase.TC003_LoginDDT" name="verify_loginDDT" time="3.889">
    <failure message="Exception occurred during test execution." type="java.lang.AssertionError">
      <![CDATA[java.lang.AssertionError: Exception occurred during test execution.
at org.testng.Assert.fail(Assert.java:111)
at testCase.TC003_LoginDDT.verify_loginDDT(TC003_LoginDDT.java:57)
at java.base/jdk.internal.reflect.NativeMethodAccessorImpl.invoke0(Native Method)
at java.base/jdk.internal.reflect.NativeMethodAccessorImpl.invoke(NativeMethodAccessorImpl.java:62)
at java.base/jdk.internal.reflect.DelegatingMethodAccessorImpl.invoke(DelegatingMethodAccessorImpl.java:43)
at java.base/java.lang.reflect.Method.invoke(Method.java:566)
at org.testng.internal.invokers.MethodInvocationHelper.invokeMethod(MethodInvocationHelper.java:141)
at org.testng.internal.invokers.TestInvoker.invokeMethod(TestInvoker.java:686)
at org.testng.internal.invokers.TestInvoker.invokeTestMethod(TestInvoker.java:230)
at org.testng.internal.invokers.MethodRunner.runInSequence(MethodRunner.java:63)
at org.testng.internal.invokers.TestInvoker$MethodInvocationAgent.invoke(TestInvoker.java:992)
at org.testng.internal.invokers.TestInvoker.invokeTestMethods(TestInvoker.java:203)
at org.testng.internal.invokers.TestMethodWorker.invokeTestMethods(TestMethodWorker.java:154)
at org.testng.internal.invokers.TestMethodWorker.run(TestMethodWorker.java:134)
at java.base/java.util.ArrayList.forEach(ArrayList.java:1541)
at org.testng.TestRunner.privateRun(TestRunner.java:739)
at org.testng.TestRunner.run(TestRunner.java:614)
at org.testng.SuiteRunner.runTest(SuiteRunner.java:421)
at org.testng.SuiteRunner.runSequentially(SuiteRunner.java:413)
at org.testng.SuiteRunner.privateRun(SuiteRunner.java:373)
at org.testng.SuiteRunner.run(SuiteRunner.java:312)
at org.testng.SuiteRunnerWorker.runSuite(SuiteRunnerWorker.java:52)
at org.testng.SuiteRunnerWorker.run(SuiteRunnerWorker.java:95)
at org.testng.TestNG.runSuitesSequentially(TestNG.java:1274)
at org.testng.TestNG.runSuitesLocally(TestNG.java:1208)
at org.testng.TestNG.runSuites(TestNG.java:1112)
at org.testng.TestNG.run(TestNG.java:1079)
at org.apache.maven.surefire.testng.TestNGExecutor.run(TestNGExecutor.java:308)
at org.apache.maven.surefire.testng.TestNGXmlTestSuite.execute(TestNGXmlTestSuite.java:71)
at org.apache.maven.surefire.testng.TestNGProvider.invoke(TestNGProvider.java:113)
at org.apache.maven.surefire.booter.ForkedBooter.runSuitesInProcess(ForkedBooter.java:385)
at org.apache.maven.surefire.booter.ForkedBooter.execute(ForkedBooter.java:162)
at org.apache.maven.surefire.booter.ForkedBooter.run(ForkedBooter.java:507)
at org.apache.maven.surefire.booter.ForkedBooter.main(ForkedBooter.java:495)
]]>
    </failure>
  </testcase> <!-- verify_loginDDT -->
</testsuite> <!-- testCase.TC003_LoginDDT -->
